<?xml version="1.0" encoding="utf-8"?>
<robot xmlns:xacro="http://www.ros.org/wiki/xacro" name="hand">
  <xacro:macro name="hand" params="connected_to:='' ns:='' rpy:='0 0 0' xyz:='0 0 0' ">
    <xacro:unless value="${connected_to == ''}">
      <joint name="${ns}_hand_joint" type="fixed">
        <parent link="${connected_to}"/>
        <child link="${ns}_hand"/>
        <origin xyz="${xyz}" rpy="${rpy}"/>
      </joint>
    </xacro:unless>
    <material name="hand_mat">
      <color rgba="0.9 0.6 0 1"/>
    </material>
    <link name="${ns}_hand">
      <visual>
        <geometry>
          <mesh filename="package://robocol_new_arm/meshes/visual/hand.stl" scale="0.1 0.1 0.1"/>
        </geometry>
        <material name="joints_mat"/>
      </visual>
      <collision>
        <geometry>
          <mesh filename="package://robocol_new_arm/meshes/collision/hand.stl" scale="0.1 0.1 0.1"/>
        </geometry>
      </collision>
    </link>
    <link name="${ns}_leftfinger">
      <visual>
        <geometry>
          <mesh filename="package://robocol_new_arm/meshes/visual/finger.stl" scale="0.1 0.1 0.1"/>
        </geometry>
        <material name="joints_mat"/>
      </visual>
      <collision>
        <geometry>
          <mesh filename="package://robocol_new_arm/meshes/collision/finger.stl" scale="0.1 0.1 0.1"/>
        </geometry>
      </collision>
    </link>
    <link name="${ns}_rightfinger">
      <visual>
        <origin xyz="0 0 0" rpy="0 0 ${pi}"/>
        <geometry>
          <mesh filename="package://robocol_new_arm/meshes/visual/finger.stl" scale="0.1 0.1 0.1"/>
        </geometry>
        <material name="joints_mat"/>
      </visual>
      <collision>
        <origin xyz="0 0 0" rpy="0 0 ${pi}"/>
        <geometry>
          <mesh filename="package://robocol_new_arm/meshes/collision/finger.stl" scale="0.1 0.1 0.1"/>
        </geometry>
      </collision>
    </link>
    <joint name="${ns}_finger_joint1" type="prismatic">
      <parent link="${ns}_hand"/>
      <child link="${ns}_leftfinger"/>
      <origin xyz="-0.5 0 0.65" rpy="0 ${pi/2} 0"/>
      <axis xyz="0 0 1"/>
      <limit effort="20" lower="0.0" upper="0.28" velocity="0.2"/>
    </joint>
    <joint name="${ns}_finger_joint2" type="prismatic">
      <parent link="${ns}_hand"/>
      <child link="${ns}_rightfinger"/>
      <origin xyz="0.5 0 0.65" rpy="0 ${-pi/2} 0"/>
      <axis xyz="0 0 1"/>
      <limit effort="20" lower="0.0" upper="0.28" velocity="0.2"/>
      <mimic joint="${ns}_finger_joint1" />
    </joint>
  </xacro:macro>
</robot>
